Workbook

Sheet air_EF_update_221117
A1: INPUT_TABLE
A2: Variable ID
A3: GLIMPSEInputEmissCoef
A5: region | B5: supplysector | C5: tranSubsector | D5: stub-technology | E5: year | F5: pollutant | G5: value | H5: type
A6: all states | B6: trn_pass | C6: Domestic Aviation | D6: Liquids | E6: 2015 | F6: NOx | G6: ='Calcs (2)'!K51 -> 0.029417445 | H6: input-driver
A7: all states | B7: trn_pass | C7: Domestic Aviation | D7: Liquids | E7: 2020 | F7: NOx | G7: ='Calcs (2)'!K52 -> 0.029417445 | H7: input-driver
A8: all states | B8: trn_pass | C8: Domestic Aviation | D8: Liquids | E8: 2025 | F8: NOx | G8: ='Calcs (2)'!K53 -> 0.029417445 | H8: input-driver
A9: all states | B9: trn_pass | C9: Domestic Aviation | D9: Liquids | E9: 2030 | F9: NOx | G9: ='Calcs (2)'!K54 -> 0.029417445 | H9: input-driver
A10: all states | B10: trn_pass | C10: Domestic Aviation | D10: Liquids | E10: 2035 | F10: NOx | G10: ='Calcs (2)'!K55 -> 0.029417445 | H10: input-driver
A11: all states | B11: trn_pass | C11: Domestic Aviation | D11: Liquids | E11: 2040 | F11: NOx | G11: =G10 -> 0.029417445 | H11: input-driver
A12: all states | B12: trn_pass | C12: Domestic Aviation | D12: Liquids | E12: 2045 | F12: NOx | G12: =G11 -> 0.029417445 | H12: input-driver
A13: all states | B13: trn_pass | C13: Domestic Aviation | D13: Liquids | E13: 2050 | F13: NOx | G13: =G12 -> 0.029417445 | H13: input-driver
A14: all states | B14: trn_pass | C14: Domestic Aviation | D14: Liquids | E14: 2015 | F14: SO2_1 | G14: ='Calcs (2)'!K56 -> 0.003972564 | H14: input-driver
A15: all states | B15: trn_pass | C15: Domestic Aviation | D15: Liquids | E15: 2020 | F15: SO2_1 | G15: ='Calcs (2)'!K57 -> 0.003972564 | H15: input-driver
A16: all states | B16: trn_pass | C16: Domestic Aviation | D16: Liquids | E16: 2025 | F16: SO2_1 | G16: ='Calcs (2)'!K58 -> 0.003972564 | H16: input-driver
A17: all states | B17: trn_pass | C17: Domestic Aviation | D17: Liquids | E17: 2030 | F17: SO2_1 | G17: ='Calcs (2)'!K59 -> 0.003972564 | H17: input-driver
A18: all states | B18: trn_pass | C18: Domestic Aviation | D18: Liquids | E18: 2035 | F18: SO2_1 | G18: ='Calcs (2)'!K60 -> 0.003972564 | H18: input-driver
A19: all states | B19: trn_pass | C19: Domestic Aviation | D19: Liquids | E19: 2040 | F19: SO2_1 | G19: =G18 -> 0.003972564 | H19: input-driver
A20: all states | B20: trn_pass | C20: Domestic Aviation | D20: Liquids | E20: 2045 | F20: SO2_1 | G20: =G19 -> 0.003972564 | H20: input-driver
A21: all states | B21: trn_pass | C21: Domestic Aviation | D21: Liquids | E21: 2050 | F21: SO2_1 | G21: =G20 -> 0.003972564 | H21: input-driver
A22: all states | B22: trn_pass | C22: Domestic Aviation | D22: Liquids | E22: 2015 | F22: PM10 | G22: ='Calcs (2)'!K66 -> 0.0032760985 | H22: input-driver
A23: all states | B23: trn_pass | C23: Domestic Aviation | D23: Liquids | E23: 2020 | F23: PM10 | G23: ='Calcs (2)'!K67 -> 0.0032760985 | H23: input-driver
A24: all states | B24: trn_pass | C24: Domestic Aviation | D24: Liquids | E24: 2025 | F24: PM10 | G24: ='Calcs (2)'!K68 -> 0.0032760985 | H24: input-driver
A25: all states | B25: trn_pass | C25: Domestic Aviation | D25: Liquids | E25: 2030 | F25: PM10 | G25: ='Calcs (2)'!K69 -> 0.0032760985 | H25: input-driver
A26: all states | B26: trn_pass | C26: Domestic Aviation | D26: Liquids | E26: 2035 | F26: PM10 | G26: ='Calcs (2)'!K70 -> 0.0032760985 | H26: input-driver
A27: all states | B27: trn_pass | C27: Domestic Aviation | D27: Liquids | E27: 2040 | F27: PM10 | G27: =G26 -> 0.0032760985 | H27: input-driver
A28: all states | B28: trn_pass | C28: Domestic Aviation | D28: Liquids | E28: 2045 | F28: PM10 | G28: =G27 -> 0.0032760985 | H28: input-driver
A29: all states | B29: trn_pass | C29: Domestic Aviation | D29: Liquids | E29: 2050 | F29: PM10 | G29: =G28 -> 0.0032760985 | H29: input-driver
A30: all states | B30: trn_pass | C30: Domestic Aviation | D30: Liquids | E30: 2015 | F30: PM2.5 | G30: ='Calcs (2)'!K61 -> 0.0028640925 | H30: input-driver
A31: all states | B31: trn_pass | C31: Domestic Aviation | D31: Liquids | E31: 2020 | F31: PM2.5 | G31: ='Calcs (2)'!K62 -> 0.0028640925 | H31: input-driver
A32: all states | B32: trn_pass | C32: Domestic Aviation | D32: Liquids | E32: 2025 | F32: PM2.5 | G32: ='Calcs (2)'!K63 -> 0.0028640925 | H32: input-driver
A33: all states | B33: trn_pass | C33: Domestic Aviation | D33: Liquids | E33: 2030 | F33: PM2.5 | G33: ='Calcs (2)'!K64 -> 0.0028640925 | H33: input-driver
A34: all states | B34: trn_pass | C34: Domestic Aviation | D34: Liquids | E34: 2035 | F34: PM2.5 | G34: ='Calcs (2)'!K65 -> 0.0028640925 | H34: input-driver
A35: all states | B35: trn_pass | C35: Domestic Aviation | D35: Liquids | E35: 2040 | F35: PM2.5 | G35: =G34 -> 0.0028640925 | H35: input-driver
A36: all states | B36: trn_pass | C36: Domestic Aviation | D36: Liquids | E36: 2045 | F36: PM2.5 | G36: =G35 -> 0.0028640925 | H36: input-driver
A37: all states | B37: trn_pass | C37: Domestic Aviation | D37: Liquids | E37: 2050 | F37: PM2.5 | G37: =G36 -> 0.0028640925 | H37: input-driver
A38: all states | B38: trn_pass | C38: Domestic Aviation | D38: Liquids | E38: 2015 | F38: NMVOC | G38: ='Calcs (2)'!K71 -> 0.0087078873 | H38: input-driver
A39: all states | B39: trn_pass | C39: Domestic Aviation | D39: Liquids | E39: 2020 | F39: NMVOC | G39: ='Calcs (2)'!K72 -> 0.0087078873 | H39: input-driver
A40: all states | B40: trn_pass | C40: Domestic Aviation | D40: Liquids | E40: 2025 | F40: NMVOC | G40: ='Calcs (2)'!K73 -> 0.0087078873 | H40: input-driver
A41: all states | B41: trn_pass | C41: Domestic Aviation | D41: Liquids | E41: 2030 | F41: NMVOC | G41: ='Calcs (2)'!K74 -> 0.0087078873 | H41: input-driver
...

Sheet Calcs (2)
A1: Step 1. Obtain emissions from 2016fj inventory and its projections
A3: Emissions from EPA projections
A4: EPA Inventory & Projections | D4: NOx | J4: SO2 | P4: PM25 | V4: PM10 | AB4: VOC | AH4: CO
A5: Year | D5: 2016 | E5: 2023 | F5: 2026 | G5: 2032 | J5: 2016 | K5: 2023 | L5: 2026 | M5: 2032 | P5: 2016 | Q5: 2023 | R5: 2026 | S5: 2032 | V5: 2016 | W5: 2023 | X5: 2026 | Y5: 2032 | AB5: 2016 | AC5: 2023 | AD5: 2026 | AE5: 2032 | AH5: 2016 | AI5: 2023 | AJ5: 2026 | AK5: 2032
A6: airports | D6: 132589.3 | E6: 152058.86 | F6: 158429.37 | G6: 172103.67 | J6: 16017.545 | K6: 18528.13 | L6: 19357.595 | M6: 21135.097 | P6: 9137.8722 | Q6: 9224.148 | R6: 9374.7199 | S6: 9718.6633 | V6: 10449.508 | W6: 10508.181 | X6: 10672.35 | Y6: 11047.593 | AB6: 56764.294 | AC6: 60616.433 | AD6: 62380.275 | AE6: 66144.971 | AH6: 505323.97 | AI6: 537577.79 | AJ6: 554024.11 | AK6: 589250.46
A8: Step 2. Interpolate to obtain values for 2015
A10: Interpolated values
D11: NOx | E11: SO2 | F11: PM25 | G11: PM10 | H11: VOC | I11: CO
D12: 2015 | E12: 2015 | F12: 2015 | G12: 2015 | H12: 2015 | I12: 2015
A13: airports | D13: =-(E6-D6)/7+D6 -> 129807.93 | E13: =-(K6-J6)/7+J6 -> 15658.889 | F13: =-(Q6-P6)/7+P6 -> 9125.5471 | G13: =-(W6-V6)/7+V6 -> 10441.126 | H13: =-(AC6-AB6)/7+AB6 -> 56213.989 | I13: =-(AI6-AH6)/7+AH6 -> 500716.28
A15: Step 3. Convert to Tg
D17: NOx | E17: SO2 | F17: PM25 | G17: PM10 | H17: VOC | I17: CO
D18: 2015 | E18: 2015 | F18: 2015 | G18: 2015 | H18: 2015 | I18: 2015
A19: airports | D19: =D13*0.000000907185 -> 0.11775981 | E19: =E13*0.000000907185 -> 0.01420551 | F19: =F13*0.000000907185 -> 0.0082785594 | G19: =G13*0.000000907185 -> 0.0094720328 | H19: =H13*0.000000907185 -> 0.050996488 | I19: =I13*0.000000907185 -> 0.4542423
A22: Step 4. Fuel use from GCAM-USA
A24: scenario | D24: region | E24: subsector | F24: technology | G24: 2015
A25: GLIMPSE-Reference2,date=2022-28-7T14:25:16-04:00 | D25: Total | E25: Domestic Aviation | F25: BEV | G25: 0
A26: GLIMPSE-Reference2,date=2022-28-7T14:25:16-04:00 | D26: Total | E26: Domestic Aviation | F26: Hydrogen | G26: 0
A27: GLIMPSE-Reference2,date=2022-28-7T14:25:16-04:00 | D27: Total | E27: Domestic Aviation | F27: Liquids | G27: 2.55
A28: GLIMPSE-Reference2,date=2022-28-7T14:25:16-04:00 | D28: Total | E28: International Aviation | F28: BEV | G28: 0
A29: GLIMPSE-Reference2,date=2022-28-7T14:25:16-04:00 | D29: Total | E29: International Aviation | F29: Hydrogen | G29: 0
A30: GLIMPSE-Reference2,date=2022-28-7T14:25:16-04:00 | D30: Total | E30: International Aviation | F30: Liquids | G30: 0.668
F32: Dom | G32: =G27 -> 2.55
F33: Int'l | G33: =G30 -> 0.668
F34: Total | G34: =G33+G32 -> 3.218
A37: Step 5. Calculate 2025 Efs
D38: NOx | E38: SO2 | F38: PM25 | G38: PM10 | H38: VOC | I38: CO
D39: 2015 | E39: 2015 | F39: 2015 | G39: 2015 | H39: 2015 | I39: 2015
B40: NEI | C40: airports | D40: =D19/$G$34 -> 0.036594098 | E40: =E19/$G$34 -> 0.0044143908 | F40: =F19/$G$34 -> 0.0025725791 | G40: =G19/$G$34 -> 0.0029434533 | H40: =H19/$G$34 -> 0.015847262 | I40: =I19/$G$34 -> 0.14115671
B41: GCAM | C41: air | D41: =GCAMResult_preScale!H21/$G$34 -> 0 | E41: =P51/G34 -> 0.0093573247 | F41: =P52/G34 -> 0.00080015265 | G41: =Q53/G34 -> 0.00091468406 | H41: =P54/G34 -> 0.0078508823 | I41: =P55/G34 -> 0.043908932
D42: =D40/D41 -> #DIV/0! | E42: =E40/E41 -> 0.47175779 | F42: =F40/F41 -> 3.2151103 | G42: =G40/G41 -> 3.218 | H42: =H40/H41 -> 2.0185326 | I42: =I40/I41 -> 3.2147608
A45: Step 6. Compare emissions with unscaled to develop scaling factors
O47: 2015 Pre-Scaled emissions | Q47: 2015 Inventory
Q48: from NEI
G49: Original emission factors | K49: Scaled emission factors | P49: Air | Q49: Airports | R49: Scaling
I50: Domestic air | J50: International air | K50: Domestic Air | L50: International Air | O50: NOx | P50: =GCAMResult_preScale!G28 -> 0.056587943 | Q50: =D19/G34 -> 0.036594098 | R50: =Q50/P50 -> 0.6466766
F51: NOx | G51: 2015 | I51: =GCAMResult_preScale!H28 -> 0.045490196 | J51: =GCAMResult_preScale!I28 -> 0.098952096 | K51: =I51*$R$50 -> 0.029417445 | L51: =J51*$R$50 -> 0.063990005 | O51: SO2 | P51: =GCAMResult_preScale!G29 -> 0.030111871 | Q51: =E19/G34 -> 0.0044143908 | R51: =Q51/P51 -> 0.14659969
G52: 2020 | I52: =I51 -> 0.045490196 | J52: =J51 -> 0.098952096 | K52: =I52*$R$50 -> 0.029417445 | L52: =J52*$R$50 -> 0.063990005 | O52: PM2.5 | P52: =GCAMResult_preScale!G30 -> 0.0025748912 | Q52: =F19/G34 -> 0.0025725791 | R52: =Q52/P52 -> 0.99910203
G53: 2025 | I53: =I52 -> 0.045490196 | J53: =J52 -> 0.098952096 | K53: =I53*$R$50 -> 0.029417445 | L53: =J53*$R$50 -> 0.063990005 | O53: PM10 | P53: =GCAMResult_preScale!G31 -> 0.0033436917 | Q53: =G19/G34 -> 0.0029434533 | R53: =Q53/P53 -> 0.88030044
G54: 2030 | I54: =I53 -> 0.045490196 | J54: =J53 -> 0.098952096 | K54: =I54*$R$50 -> 0.029417445 | L54: =J54*$R$50 -> 0.063990005 | O54: NMVOC | P54: =GCAMResult_preScale!G32 -> 0.025264139 | Q54: =H19/G34 -> 0.015847262 | R54: =Q54/P54 -> 0.62726307
...

Sheet GCAMResult_preScale
A1: scenario | B1: region | C1: sector | D1: subsector | E1: subsector | F1: technology | G1: GHG | H1: 2015 | I1: 2020 | J1: 2025 | K1: 2030 | L1: 2035 | M1: 2040 | N1: 2045 | O1: 2050 | P1: Units
A2: GLIMPSE-Ref-20221117-RPS,date=2022-17-11T08:29:06-05:00 | B2: Total | C2: trn_aviation_intl | D2: International Aviation | E2: Liquids | F2: N/A | G2: BC | H2: 0.000901 | I2: 0.000952 | J2: 0.000931 | K2: 0.00092 | L2: 0.000914 | M2: 0.000969 | N2: 0.00102 | O2: 0.00107 | P2: Tg
A3: GLIMPSE-Ref-20221117-RPS,date=2022-17-11T08:29:06-05:00 | B3: Total | C3: trn_aviation_intl | D3: International Aviation | E3: Liquids | F3: N/A | G3: CO | H3: 0.0707 | I3: 0.0747 | J3: 0.073 | K3: 0.0722 | L3: 0.0717 | M3: 0.076 | N3: 0.0802 | O3: 0.084 | P3: Tg
A4: GLIMPSE-Ref-20221117-RPS,date=2022-17-11T08:29:06-05:00 | B4: Total | C4: trn_aviation_intl | D4: International Aviation | E4: Liquids | F4: N/A | G4: CO2 | H4: 13.1 | I4: 13.8 | J4: 13.5 | K4: 13.4 | L4: 13.3 | M4: 14.1 | N4: 14.9 | O4: 15.6 | P4: MTC
A5: GLIMPSE-Ref-20221117-RPS,date=2022-17-11T08:29:06-05:00 | B5: Total | C5: trn_aviation_intl | D5: International Aviation | E5: Liquids | F5: N/A | G5: NH3 | H5: 0.00366 | I5: 0.00386 | J5: 0.00378 | K5: 0.00373 | L5: 0.00371 | M5: 0.00393 | N5: 0.00415 | O5: 0.00435 | P5: Tg
A6: GLIMPSE-Ref-20221117-RPS,date=2022-17-11T08:29:06-05:00 | B6: Total | C6: trn_aviation_intl | D6: International Aviation | E6: Liquids | F6: N/A | G6: NMVOC | H6: 0.0459 | I6: 0.0484 | J6: 0.0474 | K6: 0.0468 | L6: 0.0465 | M6: 0.0493 | N6: 0.0521 | O6: 0.0545 | P6: Tg
A7: GLIMPSE-Ref-20221117-RPS,date=2022-17-11T08:29:06-05:00 | B7: Total | C7: trn_aviation_intl | D7: International Aviation | E7: Liquids | F7: N/A | G7: NOx | H7: 0.0661 | I7: 0.0698 | J7: 0.0683 | K7: 0.0675 | L7: 0.0671 | M7: 0.0711 | N7: 0.0751 | O7: 0.0786 | P7: Tg
A8: GLIMPSE-Ref-20221117-RPS,date=2022-17-11T08:29:06-05:00 | B8: Total | C8: trn_aviation_intl | D8: International Aviation | E8: Liquids | F8: N/A | G8: OC | H8: 0.00044 | I8: 0.000464 | J8: 0.000454 | K8: 0.000449 | L8: 0.000446 | M8: 0.000473 | N8: 0.000499 | O8: 0.000523 | P8: Tg
A9: GLIMPSE-Ref-20221117-RPS,date=2022-17-11T08:29:06-05:00 | B9: Total | C9: trn_aviation_intl | D9: International Aviation | E9: Liquids | F9: N/A | G9: PM10 | H9: 0.00127 | I9: 0.00134 | J9: 0.00131 | K9: 0.00129 | L9: 0.00128 | M9: 0.00136 | N9: 0.00144 | O9: 0.0015 | P9: Tg
A10: GLIMPSE-Ref-20221117-RPS,date=2022-17-11T08:29:06-05:00 | B10: Total | C10: trn_aviation_intl | D10: International Aviation | E10: Liquids | F10: N/A | G10: PM2.5 | H10: 0.000976 | I10: 0.00103 | J10: 0.00101 | K10: 0.000996 | L10: 0.00099 | M10: 0.00105 | N10: 0.00111 | O10: 0.00116 | P10: Tg
A11: GLIMPSE-Ref-20221117-RPS,date=2022-17-11T08:29:06-05:00 | B11: Total | C11: trn_aviation_intl | D11: International Aviation | E11: Liquids | F11: N/A | G11: SO2 | H11: 0.0278 | I11: 0.0294 | J11: 0.0287 | K11: 0.0284 | L11: 0.0282 | M11: 0.0299 | N11: 0.0316 | O11: 0.033 | P11: Tg
A12: GLIMPSE-Ref-20221117-RPS,date=2022-17-11T08:29:06-05:00 | B12: Total | C12: trn_pass | D12: Domestic Aviation | E12: Liquids | F12: N/A | G12: BC | H12: 0.00415 | I12: 0.0044 | J12: 0.00463 | K12: 0.00476 | L12: 0.0047 | M12: 0.00489 | N12: 0.00492 | O12: 0.00467 | P12: Tg
... A20: GLIMPSE-Ref-20221117-RPS,date=2022-17-11T08:29:06-05:00 | B20: Total | C20: trn_pass | D20: Domestic Aviation | E20: Liquids | F20: N/A | G20: SO2 | H20: 0.0691 | I20: 0.0733 | J20: 0.0771 | K20: 0.0792 | L20: 0.0783 | M20: 0.0814 | N20: 0.082 | O20: 0.0778 | P20: Tg
A22: scenario | B22: region | D22: subsector | E22: technology | H22: 2015 | I22: 2020 | J22: 2025 | K22: 2030 | L22: 2035 | M22: 2040 | N22: 2045 | O22: 2050 | P22: Units
A23: GLIMPSE-Ref-20221117-RPS,date=2022-17-11T08:29:06-05:00 | B23: Total | D23: Domestic Aviation | E23: Liquids | H23: 2.55 | I23: 2.71 | J23: 2.85 | K23: 2.93 | L23: 2.89 | M23: 3.01 | N23: 3.03 | O23: 2.87 | P23: EJ
A24: GLIMPSE-Ref-20221117-RPS,date=2022-17-11T08:29:06-05:00 | B24: Total | D24: International Aviation | E24: Liquids | H24: 0.668 | I24: 0.706 | J24: 0.69 | K24: 0.682 | L24: 0.678 | M24: 0.718 | N24: 0.758 | O24: 0.794 | P24: EJ
H25: =SUM(H23:H24) -> 3.218 | I25: =SUM(I23:I24) -> 3.416 | J25: =SUM(J23:J24) -> 3.54 | K25: =SUM(K23:K24) -> 3.612 | L25: =SUM(L23:L24) -> 3.568 | M25: =SUM(M23:M24) -> 3.728 | N25: =SUM(N23:N24) -> 3.788 | O25: =SUM(O23:O24) -> 3.664
E27: Initial Efs | G27: overall | H27: dom | I27: intl
F28: NOx | G28: =(H7+H16)/H25 -> 0.056587943 | H28: =H16/H23 -> 0.045490196 | I28: =H7/H24 -> 0.098952096
F29: SO2 | G29: =(H11+H20)/H25 -> 0.030111871 | H29: =H20/H23 -> 0.027098039 | I29: =H11/H24 -> 0.041616766
F30: PM2.5 | G30: =(H10+H19)/H25 -> 0.0025748912 | H30: =H19/H23 -> 0.0028666667 | I30: =H10/H24 -> 0.0014610778
F31: PM10 | G31: =(H9+H18)/H25 -> 0.0033436917 | H31: =H18/H23 -> 0.0037215686 | I31: =H9/H23 -> 0.00049803922
F32: NMVOC | G32: =(H6+H15)/H25 -> 0.025264139 | H32: =H15/H23 -> 0.013882353 | I32: =H6/H24 -> 0.068712575
F33: CO | G33: =(H3+H13)/H25 -> 0.14129894 | H33: =H13/H23 -> 0.15058824 | I33: =H3/H24 -> 0.10583832
F34: NH3 | G34: =H5/H24 -> 0.0054790419
