Workbook

Sheet emission_calcs_marine_221101_sc
A1: INPUT_TABLE
A2: Variable ID
A3: GLIMPSEInputEmissCoef
A5: region | B5: supplysector | C5: tranSubsector | D5: stub-technology | E5: year | F5: pollutant | G5: value | H5: type
A6: all states | B6: trn_freight | C6: Domestic Ship | D6: Liquids | E6: 2015 | F6: NOx | G6: ='Calcs (2)'!H80 -> 0.46064988 | H6: input-driver
A7: all states | B7: trn_freight | C7: Domestic Ship | D7: Liquids | E7: 2020 | F7: NOx | G7: ='Calcs (2)'!H81 -> 0.3540314 | H7: input-driver
A8: all states | B8: trn_freight | C8: Domestic Ship | D8: Liquids | E8: 2025 | F8: NOx | G8: ='Calcs (2)'!H82 -> 0.21665867 | H8: input-driver
A9: all states | B9: trn_freight | C9: Domestic Ship | D9: Liquids | E9: 2030 | F9: NOx | G9: ='Calcs (2)'!H83 -> 0.18107371 | H9: input-driver
A10: all states | B10: trn_freight | C10: Domestic Ship | D10: Liquids | E10: 2035 | F10: NOx | G10: ='Calcs (2)'!H84 -> 0.13710869 | H10: input-driver
A11: all states | B11: trn_freight | C11: Domestic Ship | D11: Liquids | E11: 2040 | F11: NOx | G11: =G10 -> 0.13710869 | H11: input-driver
A12: all states | B12: trn_freight | C12: Domestic Ship | D12: Liquids | E12: 2045 | F12: NOx | G12: =G11 -> 0.13710869 | H12: input-driver
A13: all states | B13: trn_freight | C13: Domestic Ship | D13: Liquids | E13: 2050 | F13: NOx | G13: =G12 -> 0.13710869 | H13: input-driver
A14: all states | B14: trn_freight | C14: Domestic Ship | D14: Liquids | E14: 2015 | F14: SO2_1 | G14: ='Calcs (2)'!H85 -> 0.0018062427 | H14: input-driver
A15: all states | B15: trn_freight | C15: Domestic Ship | D15: Liquids | E15: 2020 | F15: SO2_1 | G15: ='Calcs (2)'!H86 -> 0.001202494 | H15: input-driver
A16: all states | B16: trn_freight | C16: Domestic Ship | D16: Liquids | E16: 2025 | F16: SO2_1 | G16: ='Calcs (2)'!H87 -> 0.00045424123 | H16: input-driver
A17: all states | B17: trn_freight | C17: Domestic Ship | D17: Liquids | E17: 2030 | F17: SO2_1 | G17: ='Calcs (2)'!H88 -> 0.00047844655 | H17: input-driver
A18: all states | B18: trn_freight | C18: Domestic Ship | D18: Liquids | E18: 2035 | F18: SO2_1 | G18: ='Calcs (2)'!H89 -> 0.00042774509 | H18: input-driver
A19: all states | B19: trn_freight | C19: Domestic Ship | D19: Liquids | E19: 2040 | F19: SO2_1 | G19: =G18 -> 0.00042774509 | H19: input-driver
A20: all states | B20: trn_freight | C20: Domestic Ship | D20: Liquids | E20: 2045 | F20: SO2_1 | G20: =G19 -> 0.00042774509 | H20: input-driver
A21: all states | B21: trn_freight | C21: Domestic Ship | D21: Liquids | E21: 2050 | F21: SO2_1 | G21: =G20 -> 0.00042774509 | H21: input-driver
A22: all states | B22: trn_freight | C22: Domestic Ship | D22: Liquids | E22: 2015 | F22: PM10 | G22: ='Calcs (2)'!H95 -> 0.012613913 | H22: input-driver
A23: all states | B23: trn_freight | C23: Domestic Ship | D23: Liquids | E23: 2020 | F23: PM10 | G23: ='Calcs (2)'!H96 -> 0.0097041228 | H23: input-driver
A24: all states | B24: trn_freight | C24: Domestic Ship | D24: Liquids | E24: 2025 | F24: PM10 | G24: ='Calcs (2)'!H97 -> 0.0059534454 | H24: input-driver
A25: all states | B25: trn_freight | C25: Domestic Ship | D25: Liquids | E25: 2030 | F25: PM10 | G25: ='Calcs (2)'!H98 -> 0.0049598167 | H25: input-driver
A26: all states | B26: trn_freight | C26: Domestic Ship | D26: Liquids | E26: 2035 | F26: PM10 | G26: ='Calcs (2)'!H99 -> 0.0037390042 | H26: input-driver
A27: all states | B27: trn_freight | C27: Domestic Ship | D27: Liquids | E27: 2040 | F27: PM10 | G27: =G26 -> 0.0037390042 | H27: input-driver
A28: all states | B28: trn_freight | C28: Domestic Ship | D28: Liquids | E28: 2045 | F28: PM10 | G28: =G27 -> 0.0037390042 | H28: input-driver
A29: all states | B29: trn_freight | C29: Domestic Ship | D29: Liquids | E29: 2050 | F29: PM10 | G29: =G28 -> 0.0037390042 | H29: input-driver
A30: all states | B30: trn_freight | C30: Domestic Ship | D30: Liquids | E30: 2015 | F30: PM2.5 | G30: ='Calcs (2)'!H90 -> 0.0122253 | H30: input-driver
A31: all states | B31: trn_freight | C31: Domestic Ship | D31: Liquids | E31: 2020 | F31: PM2.5 | G31: ='Calcs (2)'!H91 -> 0.0094051622 | H31: input-driver
A32: all states | B32: trn_freight | C32: Domestic Ship | D32: Liquids | E32: 2025 | F32: PM2.5 | G32: ='Calcs (2)'!H92 -> 0.0057700446 | H32: input-driver
A33: all states | B33: trn_freight | C33: Domestic Ship | D33: Liquids | E33: 2030 | F33: PM2.5 | G33: ='Calcs (2)'!H93 -> 0.0048070371 | H33: input-driver
A34: all states | B34: trn_freight | C34: Domestic Ship | D34: Liquids | E34: 2035 | F34: PM2.5 | G34: ='Calcs (2)'!H94 -> 0.0036238464 | H34: input-driver
A35: all states | B35: trn_freight | C35: Domestic Ship | D35: Liquids | E35: 2040 | F35: PM2.5 | G35: =G34 -> 0.0036238464 | H35: input-driver
A36: all states | B36: trn_freight | C36: Domestic Ship | D36: Liquids | E36: 2045 | F36: PM2.5 | G36: =G35 -> 0.0036238464 | H36: input-driver
A37: all states | B37: trn_freight | C37: Domestic Ship | D37: Liquids | E37: 2050 | F37: PM2.5 | G37: =G36 -> 0.0036238464 | H37: input-driver
A38: all states | B38: trn_freight | C38: Domestic Ship | D38: Liquids | E38: 2015 | F38: NMVOC | G38: ='Calcs (2)'!H100 -> 0.018196298 | H38: input-driver
A39: all states | B39: trn_freight | C39: Domestic Ship | D39: Liquids | E39: 2020 | F39: NMVOC | G39: ='Calcs (2)'!H101 -> 0.013827665 | H39: input-driver
A40: all states | B40: trn_freight | C40: Domestic Ship | D40: Liquids | E40: 2025 | F40: NMVOC | G40: ='Calcs (2)'!H102 -> 0.0082239691 | H40: input-driver
A41: all states | B41: trn_freight | C41: Domestic Ship | D41: Liquids | E41: 2030 | F41: NMVOC | G41: ='Calcs (2)'!H103 -> 0.0069646918 | H41: input-driver
...

Sheet Sheet1
B2: Note:
B3: Prior versions calculated emission factors based on inventory data, but vintaging meant that emissions decreased too slowly.
B4: The current version applies 2035 Efs to 2020 vintages or later, reflecting full implementation of standards.

Sheet Calcs (2)
A1: Step 1. Obtain emissions from 2016ef inventory and its projections
A3: Emissions from EPA projections
A4: EPA Inventory & Projections | B4: NOx | G4: SO2 | L4: PM25 | Q4: PM10 | V4: VOC | AA4: CO
A5: Year | B5: 2016 | C5: 2026 | D5: 2032 | G5: 2016 | H5: 2026 | I5: 2032 | L5: 2016 | M5: 2026 | N5: 2032 | Q5: 2016 | R5: 2026 | S5: 2032 | V5: 2016 | W5: 2026 | X5: 2032 | AA5: 2016 | AB5: 2026 | AC5: 2032
A6: cmv_c1c2 | B6: 167852.52 | C6: 104694.3 | D6: 88392.485 | G6: 643.2047 | H6: 245.98034 | I6: 248.88265 | L6: 4455.4393 | M6: 2786.8687 | N6: 2342.8377 | Q6: 4597.0665 | R6: 2875.4503 | S6: 2417.2949 | V6: 6617.7519 | W6: 3996.4032 | X6: 3415.1086 | AA6: 24357.913 | AB6: 24622.981 | AC6: 25074.432
A7: cmv_c3 | B7: 119015.11 | C7: 115621.52 | D7: 114946.42 | G7: 5232.3875 | H7: 6965.6453 | I7: 7649.5924 | L7: 2210.2612 | M7: 2953.4551 | N7: 3255.0081 | Q7: 2402.4585 | R7: 3210.2781 | S7: 3538.0533 | V7: 9039.2728 | W7: 12178.051 | X7: 13483.252 | AA7: 14868.891 | AB7: 19822.765 | AC7: 21859.291
A9: Step 2. Interpolate to obtain values for 2015, 2020, 2025, 2030, and 2032
A11: Interpolated values
B12: NOx | G12: SO2 | L12: PM25 | Q12: PM10 | V12: VOC | AA12: CO
B13: 2015 | C13: 2020 | D13: 2025 | E13: 2030 | F13: 2035 | G13: 2015 | H13: 2020 | I13: 2025 | J13: 2030 | K13: 2035 | L13: 2015 | M13: 2020 | N13: 2025 | O13: 2030 | P13: 2035 | Q13: 2015 | R13: 2020 | S13: 2025 | T13: 2030 | U13: 2035 | V13: 2015 | W13: 2020 | X13: 2025 | Y13: 2030 | Z13: 2035 | AA13: 2015 | AB13: 2020 | AC13: 2025 | AD13: 2030 | AE13: 2035
A14: cmv_c1c2 | B14: =(B6-C6)/10+B6 -> 174168.34 | C14: =(C6-B6)/10*4+B6 -> 142589.23 | D14: =(C6-B6)/10*11+B6 -> 98378.481 | E14: =(D6-C6)/6*4+C6 -> 93826.424 | F14: =(D6-C6)/6*9+C6 -> 80241.576 | G14: =(G6-H6)/10+G6 -> 682.92713 | H14: =(H6-G6)/10*4+G6 -> 484.31495 | I14: =(H6-G6)/10*11+G6 -> 206.2579 | J14: =(I6-H6)/6*4+H6 -> 247.91521 | K14: =(I6-H6)/6*9+H6 -> 250.33381 | L14: =(L6-M6)/10+L6 -> 4622.2964 | M14: =(M6-L6)/10*4+L6 -> 3788.0111 | N14: =(M6-L6)/10*11+L6 -> 2620.0116 | O14: =(N6-M6)/6*4+M6 -> 2490.848 | P14: =(N6-M6)/6*9+M6 -> 2120.8222 | Q14: =(Q6-R6)/10+Q6 -> 4769.2281 | R14: =(R6-Q6)/10*4+Q6 -> 3908.42 | S14: =(R6-Q6)/10*11+Q6 -> 2703.2887 | T14: =(S6-R6)/6*4+R6 -> 2570.0134 | U14: =(S6-R6)/6*9+R6 -> 2188.2172 | V14: =(V6-W6)/10+V6 -> 6879.8868 | W14: =(W6-V6)/10*4+V6 -> 5569.2124 | X14: =(W6-V6)/10*11+V6 -> 3734.2683 | Y14: =(X6-W6)/6*4+W6 -> 3608.8735 | Z14: =(X6-W6)/6*9+W6 -> 3124.4614 | AA14: =(AA6-AB6)/10+AA6 -> 24331.407 | AB14: =(AB6-AA6)/10*4+AA6 -> 24463.94 | AC14: =(AB6-AA6)/10*11+AA6 -> 24649.487 | AD14: =(AC6-AB6)/6*4+AB6 -> 24923.948 | AE14: =(AC6-AB6)/6*9+AB6 -> 25300.158
A15: cmv_c3 | B15: =(B7-C7)/10+B7 -> 119354.47 | C15: =(C7-B7)/10*4+B7 -> 117657.68 | D15: =(C7-B7)/10*11+B7 -> 115282.16 | E15: =(D7-C7)/6*4+C7 -> 115171.46 | F15: =(D7-C7)/6*9+C7 -> 114608.88 | G15: =(G7-H7)/10+G7 -> 5059.0617 | H15: =(H7-G7)/10*4+G7 -> 5925.6906 | I15: =(H7-G7)/10*11+G7 -> 7138.9711 | J15: =(I7-H7)/6*4+H7 -> 7421.61 | K15: =(I7-H7)/6*9+H7 -> 7991.5659 | L15: =(L7-M7)/10+L7 -> 2135.9418 | M15: =(M7-L7)/10*4+L7 -> 2507.5388 | N15: =(M7-L7)/10*11+L7 -> 3027.7744 | O15: =(N7-M7)/6*4+M7 -> 3154.4904 | P15: =(N7-M7)/6*9+M7 -> 3405.7846 | Q15: =(Q7-R7)/10+Q7 -> 2321.6765 | R15: =(R7-Q7)/10*4+Q7 -> 2725.5863 | S15: =(R7-Q7)/10*11+Q7 -> 3291.0601 | T15: =(S7-R7)/6*4+R7 -> 3428.7949 | U15: =(S7-R7)/6*9+R7 -> 3701.9408 | V15: =(V7-W7)/10+V7 -> 8725.395 | W15: =(W7-V7)/10*4+V7 -> 10294.784 | X15: =(W7-V7)/10*11+V7 -> 12491.928 | Y15: =(X7-W7)/6*4+W7 -> 13048.185 | Z15: =(X7-W7)/6*9+W7 -> 14135.852 | AA15: =(AA7-AB7)/10+AA7 -> 14373.503 | AB15: =(AB7-AA7)/10*4+AA7 -> 16850.441 | AC15: =(AB7-AA7)/10*11+AA7 -> 20318.153 | AD15: =(AC7-AB7)/6*4+AB7 -> 21180.449 | AE15: =(AC7-AB7)/6*9+AB7 -> 22877.554
A17: Step 3. Convert to Tg
B19: NOx | G19: SO2 | L19: PM25 | Q19: PM10 | V19: VOC | AA19: CO
B20: 2015 | C20: 2020 | D20: 2025 | E20: 2030 | F20: 2035 | G20: 2015 | H20: 2020 | I20: 2025 | J20: 2030 | K20: 2035 | L20: 2015 | M20: 2020 | N20: 2025 | O20: 2030 | P20: 2035 | Q20: 2015 | R20: 2020 | S20: 2025 | T20: 2030 | U20: 2035 | V20: 2015 | W20: 2020 | X20: 2025 | Y20: 2030 | Z20: 2035 | AA20: 2015 | AB20: 2020 | AC20: 2025 | AD20: 2030 | AE20: 2035
A21: cmv_c1c2 | B21: =B14*0.000000907185 -> 0.15800291 | C21: =C14*0.000000907185 -> 0.12935481 | D21: =D14*0.000000907185 -> 0.089247482 | E21: =E14*0.000000907185 -> 0.085117925 | F21: =F14*0.000000907185 -> 0.072793954 | G21: =G14*0.000000907185 -> 0.00061954125 | H21: =H14*0.000000907185 -> 0.00043936326 | I21: =I14*0.000000907185 -> 0.00018711407 | ... AE21: =AE14*0.000000907185 -> 0.022951924
A22: cmv_c3 | B22: =B15*0.000000907185 -> 0.10827659 | C22: =C15*0.000000907185 -> 0.10673728 | D22: =D15*0.000000907185 -> 0.10458225 | E22: =E15*0.000000907185 -> 0.10448182 | F22: =F15*0.000000907185 -> 0.10397145 | G22: =G15*0.000000907185 -> 0.0045895049 | H22: =H15*0.000000907185 -> 0.0053756976 | I22: =I15*0.000000907185 -> 0.0064763675 | ... AE22: =AE15*0.000000907185 -> 0.020754174
A24: Step 4. Get an estimate of national travel demand from GCAM-USA 5.4 outputs
A27: scenario | B27: region | C27: subsector | D27: technology | E27: 2015 | F27: 2020 | G27: 2025 | H27: 2030 | I27: 2035 | J27: 2040 | K27: 2045 | L27: 2050 | M27: Units
A28: GLIMPSE-Reference,date=2022-25-7T16:47:52-04:00 | B28: Total | C28: Domestic Ship | D28: Liquids | E28: 1050000 | F28: 1060000 | G28: 1060000 | H28: 911000 | I28: 720000 | J28: 641000 | K28: 632000 | L28: 626000 | M28: million ton-km
A29: GLIMPSE-Reference,date=2022-25-7T16:47:52-04:00 | B29: Total | C29: International Ship | D29: Liquids | E29: 13600000 | F29: 13500000 | G29: 13100000 | H29: 10700000 | I29: 7130000 | J29: 6090000 | K29: 5890000 | L29: 5850000 | M29: million ton-km
A30: GLIMPSE-Reference,date=2022-25-7T16:47:52-04:00 | B30: Total | C30: Domestic Ship | D30: BEV | E30: 0 | F30: 0 | G30: 0 | H30: 0 | I30: 12800 | J30: 34100 | K30: 88700 | L30: 186000 | M30: million ton-km
A31: GLIMPSE-Reference,date=2022-25-7T16:47:52-04:00 | B31: Total | C31: Domestic Ship | D31: FCEV | E31: 0 | F31: 0 | G31: 0 | H31: 0 | I31: 6470 | J31: 21400 | K31: 64600 | L31: 150000 | M31: million ton-km
A32: GLIMPSE-Reference,date=2022-25-7T16:47:52-04:00 | B32: Total | C32: Domestic Ship | D32: Hybrid Liquids | E32: 0 | F32: 58500 | G32: 201000 | H32: 528000 | I32: 886000 | J32: 1060000 | K32: 1130000 | L32: 1130000 | M32: million ton-km
A33: GLIMPSE-Reference,date=2022-25-7T16:47:52-04:00 | B33: Total | C33: International Ship | D33: BEV | E33: 0 | F33: 0 | G33: 0 | H33: 0 | I33: 1370 | J33: 3940 | K33: 11400 | L33: 27500 | M33: million ton-km
A34: GLIMPSE-Reference,date=2022-25-7T16:47:52-04:00 | B34: Total | C34: International Ship | D34: FCEV | E34: 0 | F34: 0 | G34: 0 | H34: 0 | I34: 17100 | J34: 67400 | K34: 255000 | L34: 776000 | M34: million ton-km
A35: GLIMPSE-Reference,date=2022-25-7T16:47:52-04:00 | B35: Total | C35: International Ship | D35: Hybrid Liquids | E35: 0 | F35: 451000 | G35: 1650000 | H35: 4960000 | I35: 9610000 | J35: 11400000 | K35: 12300000 | L35: 12700000 | M35: million ton-km
D37: Total demand | E37: 2015 | F37: 2020 | G37: 2025 | H37: 2030 | I37: 2035 | J37: 2040 | K37: 2045 | L37: 2050
D38: Domestic Ship | E38: =E28+E30+E31+E32 -> 1050000 | F38: =F28+F30+F31+F32 -> 1118500 | G38: =G28+G30+G31+G32 -> 1261000 | H38: =H28+H30+H31+H32 -> 1439000 | I38: =I28+I30+I31+I32 -> 1625270 | J38: =J28+J30+J31+J32 -> 1756500 | K38: =K28+K30+K31+K32 -> 1915300 | L38: =L28+L30+L31+L32 -> 2092000
D39: International Ship | E39: =E29+E33+E34+E35 -> 13600000 | F39: =F29+F33+F34+F35 -> 13951000 | G39: =G29+G33+G34+G35 -> 14750000 | H39: =H29+H33+H34+H35 -> 15660000 | I39: =I29+I33+I34+I35 -> 16758470 | J39: =J29+J33+J34+J35 -> 17561340 | K39: =K29+K33+K34+K35 -> 18456400 | L39: =L29+L33+L34+L35 -> 19353500
A41: Step 5. Estimate output-based emission factors based on steps 3 and 4
D43: Emission factors based on EPA emissions and GCAM service demands | J43: Deltas relative to 2015
E44: 2015 | F44: 2020 | G44: 2025 | H44: 2030 | I44: 2035 | J44: 2015 | K44: 2020 | L44: 2025 | M44: 2030 | N44: 2035
C45: Domestic Ship | D45: NOx | E45: =B21/E38 -> 1.5047896e-07 | F45: =C21/F38 -> 1.1565026e-07 | G45: =D21/G38 -> 7.0775164e-08 | H45: =E21/H38 -> 5.9150747e-08 | I45: =F21/I38 -> 4.4788838e-08 | J45: =E45/$E45 -> 1 | K45: =F45/$E45 -> 0.7685477 | L45: =G45/$E45 -> 0.47033262 | M45: =H45/$E45 -> 0.39308317 | N45: =I45/$E45 -> 0.29764186
C46: Domestic Ship | D46: SO2 | E46: =G21/E38 -> 5.9003929e-10 | F46: =H21/F38 -> 3.9281472e-10 | G46: =I21/G38 -> 1.4838547e-10 | H46: =J21/H38 -> 1.5629254e-10 | I46: =K21/I38 -> 1.3973006e-10 | J46: =E46/$E46 -> 1 | K46: =F46/$E46 -> 0.66574333 | L46: =G46/$E46 -> 0.25148405 | M46: =H46/$E46 -> 0.26488497 | N46: =I46/$E46 -> 0.23681484
C47: Domestic Ship | D47: PM2.5 | E47: =L21/E38 -> 3.993598e-09 | F47: =M21/F38 -> 3.072353e-09 | G47: =N21/G38 -> 1.8848812e-09 | H47: =O21/H38 -> 1.5702988e-09 | I47: =P21/I38 -> 1.1837898e-09 | J47: =E47/$E47 -> 1 | K47: =F47/$E47 -> 0.76931953 | L47: =G47/$E47 -> 0.4719757 | M47: =H47/$E47 -> 0.39320402 | N47: =I47/$E47 -> 0.29642188
C48: Domestic Ship | D48: PM10 | E48: =Q21/E38 -> 4.120545e-09 | F48: =R21/F38 -> 3.1700134e-09 | G48: =S21/G38 -> 1.9447922e-09 | H48: =T21/H38 -> 1.6202068e-09 | I48: =U21/I38 -> 1.221408e-09 | J48: =E48/$E48 -> 1 | K48: =F48/$E48 -> 0.76931897 | L48: =G48/$E48 -> 0.4719745 | M48: =H48/$E48 -> 0.39320206 | N48: =I48/$E48 -> 0.29641905
C49: Domestic Ship | D49: NMVOC | E49: =V21/E38 -> 5.9441239e-09 | F49: =W21/F38 -> 4.5170371e-09 | G49: =X21/G38 -> 2.6864966e-09 | H49: =Y21/H38 -> 2.2751327e-09 | I49: =Z21/I38 -> 1.7439961e-09 | J49: =E49/$E49 -> 1 | K49: =F49/$E49 -> 0.75991637 | L49: =G49/$E49 -> 0.45195838 | M49: =H49/$E49 -> 0.38275324 | N49: =I49/$E49 -> 0.29339834
C50: Domestic Ship | D50: CO | E50: =AA21/E38 -> 2.1021988e-08 | F50: =AB21/F38 -> 1.9842038e-08 | G50: =AC21/G38 -> 1.7733263e-08 | H50: =AD21/H38 -> 1.571274e-08 | I50: =AE21/I38 -> 1.4121915e-08 | J50: =E50/$E50 -> 1 | K50: =F50/$E50 -> 0.94387069 | L50: =G50/$E50 -> 0.84355788 | M50: =H50/$E50 -> 0.74744309 | N50: =I50/$E50 -> 0.67176875
E52: 2015 | F52: 2020 | G52: 2025 | H52: 2030 | I52: 2035 | J52: 2015 | K52: 2020 | L52: 2025 | M52: 2030 | N52: 2035
...

Sheet GCAMResult_preScale
A1: scenario | B1: region | C1: sector | D1: subsector | E1: subsector | F1: technology | G1: GHG | H1: 2015 | I1: 2020 | J1: 2025 | K1: 2030 | L1: 2035 | M1: 2040 | N1: 2045 | O1: 2050 | P1: Units
A2: GLIMPSE-Ref-20221117-RPS,date=2022-18-11T08:47:27-05:00 | B2: Total | C2: trn_freight | D2: Domestic Ship | E2: Liquids | F2: N/A | G2: BC | H2: 0.0154 | I2: 0.0158 | J2: 0.0154 | K2: 0.013 | L2: 0.00998 | M2: 0.0089 | N2: 0.00873 | O2: 0.00854 | P2: Tg
A3: GLIMPSE-Ref-20221117-RPS,date=2022-18-11T08:47:27-05:00 | B3: Total | C3: trn_freight | D3: Domestic Ship | E3: Liquids | F3: N/A | G3: CO | H3: 0.0221 | I3: 0.0206 | J3: 0.0181 | K3: 0.0135 | L3: 0.00931 | M3: 0.0083 | N3: 0.00814 | O3: 0.00796 | P3: Tg
A4: GLIMPSE-Ref-20221117-RPS,date=2022-18-11T08:47:27-05:00 | B4: Total | C4: trn_freight | D4: Domestic Ship | E4: Liquids | F4: N/A | G4: CO2 | H4: 6.73 | I4: 6.66 | J4: 6.53 | K4: 5.48 | L4: 4.22 | M4: 3.77 | N4: 3.69 | O4: 3.61 | P4: MTC
A5: GLIMPSE-Ref-20221117-RPS,date=2022-18-11T08:47:27-05:00 | B5: Total | C5: trn_freight | D5: Domestic Ship | E5: Liquids | F5: N/A | G5: NMVOC | H5: 0.00624 | I5: 0.0047 | J5: 0.00274 | K5: 0.00195 | L5: 0.00115 | M5: 0.00103 | N5: 0.00101 | O5: 0.000983 | P5: Tg
A6: GLIMPSE-Ref-20221117-RPS,date=2022-18-11T08:47:27-05:00 | B6: Total | C6: trn_freight | D6: Domestic Ship | E6: Liquids | F6: N/A | G6: NOx | H6: 0.158 | I6: 0.12 | J6: 0.0722 | K6: 0.0506 | L6: 0.0295 | M6: 0.0263 | N6: 0.0258 | O6: 0.0252 | P6: Tg
A7: GLIMPSE-Ref-20221117-RPS,date=2022-18-11T08:47:27-05:00 | B7: Total | C7: trn_freight | D7: Domestic Ship | E7: Liquids | F7: N/A | G7: OC | H7: 0.0127 | I7: 0.0131 | J7: 0.0128 | K7: 0.0108 | L7: 0.00828 | M7: 0.00739 | N7: 0.00724 | O7: 0.00708 | P7: Tg
A8: GLIMPSE-Ref-20221117-RPS,date=2022-18-11T08:47:27-05:00 | B8: Total | C8: trn_freight | D8: Domestic Ship | E8: Liquids | F8: N/A | G8: PM10 | H8: 0.00433 | I8: 0.0033 | J8: 0.00198 | K8: 0.00139 | L8: 0.000805 | M8: 0.000718 | N8: 0.000704 | O8: 0.000689 | P8: Tg
A9: GLIMPSE-Ref-20221117-RPS,date=2022-18-11T08:47:27-05:00 | B9: Total | C9: trn_freight | D9: Domestic Ship | E9: Liquids | F9: N/A | G9: PM2.5 | H9: 0.0042 | I9: 0.0032 | J9: 0.00192 | K9: 0.00134 | L9: 0.00078 | M9: 0.000696 | N9: 0.000682 | O9: 0.000667 | P9: Tg
A10: GLIMPSE-Ref-20221117-RPS,date=2022-18-11T08:47:27-05:00 | B10: Total | C10: trn_freight | D10: Domestic Ship | E10: Liquids | F10: N/A | G10: SO2 | H10: 0.0164 | I10: 0.0161 | J10: 0.0155 | K10: 0.013 | L10: 0.01 | M10: 0.00894 | N10: 0.00876 | O10: 0.00857 | P10: Tg
A11: GLIMPSE-Ref-20221117-RPS,date=2022-18-11T08:47:27-05:00 | B11: Total | C11: trn_shipping_intl | D11: International Ship | E11: Liquids | F11: N/A | G11: BC | H11: 0.0158 | I11: 0.0156 | J11: 0.0151 | K11: 0.0122 | L11: 0.00808 | M11: 0.00689 | N11: 0.00663 | O11: 0.00654 | P11: Tg
A12: GLIMPSE-Ref-20221117-RPS,date=2022-18-11T08:47:27-05:00 | B12: Total | C12: trn_shipping_intl | D12: International Ship | E12: Liquids | F12: N/A | G12: CO | H12: 0.013 | I12: 0.0147 | J12: 0.0162 | K12: 0.0129 | L12: 0.00861 | M12: 0.00735 | N12: 0.00707 | O12: 0.00697 | P12: Tg
... A20: GLIMPSE-Ref-20221117-RPS,date=2022-18-11T08:47:27-05:00 | B20: Total | C20: trn_shipping_intl | D20: International Ship | E20: Liquids | F20: N/A | G20: SO2 | H20: 0.538 | I20: 0.532 | J20: 0.517 | K20: 0.417 | L20: 0.276 | M20: 0.236 | N20: 0.227 | O20: 0.224 | P20: Tg
A22: scenario | B22: region | D22: subsector | E22: technology | H22: 2015 | I22: 2020 | J22: 2025 | K22: 2030 | L22: 2035 | M22: 2040 | N22: 2045 | O22: 2050 | P22: Units
A23: GLIMPSE-Ref-20221117-RPS,date=2022-18-11T08:47:27-05:00 | B23: Total | C23: Domestic Ship | G23: Liquids | H23: 0.343 | I23: 0.34 | J23: 0.333 | K23: 0.28 | L23: 0.215 | M23: 0.192 | N23: 0.188 | O23: 0.184 | P23: EJ
A24: GLIMPSE-Ref-20221117-RPS,date=2022-18-11T08:47:27-05:00 | B24: Total | C24: International Ship | G24: Liquids | H24: 1.43 | I24: 1.41 | J24: 1.37 | K24: 1.1 | L24: 0.731 | M24: 0.624 | N24: 0.6 | O24: 0.592 | P24: EJ
E26: Initial Efs | G26: Dom | H26: Intl
F27: NOx | G27: =H6/H23 -> 0.4606414 | H27: =H16/H24 -> 0.075524476
F28: SO2 | G28: =H10/H23 -> 0.047813411 | H28: =H20/H24 -> 0.37622378
F29: PM2.5 | G29: =H9/H23 -> 0.012244898 | H29: =H19/H24 -> 0.0013496503
F30: PM10 | G30: =H8/H23 -> 0.012623907 | H30: =H18/H24 -> 0.0014685315
F31: NMVOC | G31: =H5/H23 -> 0.01819242 | H31: =H15/H24 -> 0.0055174825
F32: CO | G32: =H3/H23 -> 0.064431487 | H32: =H12/H24 -> 0.0090909091
F33: NH3 | H33: =H14/H24 -> 0.00084615385
