Workbook

Sheet locomotive_EF_update_221101
A1: INPUT_TABLE
A2: Variable ID
A3: GLIMPSEInputEmissCoef
A5: region | B5: supplysector | C5: tranSubsector | D5: stub-technology | E5: year | F5: pollutant | G5: value | H5: type
A6: all states | B6: trn_freight | C6: Freight Rail | D6: Liquids | E6: 2015 | F6: SO2_1 | G6: =sulfur!C13 -> 0.00081884742 | H6: input-driver
A7: all states | B7: trn_freight | C7: Freight Rail | D7: Hybrid Liquids | E7: 2015 | F7: SO2_1 | G7: =G6 -> 0.00081884742 | H7: input-driver
A8: all states | B8: trn_pass | C8: Passenger Rail | D8: Liquids | E8: 2015 | F8: SO2_1 | G8: =G7 -> 0.00081884742 | H8: input-driver
A9: all states | B9: trn_pass | C9: Passenger Rail | D9: Liquids | E9: 2015 | F9: SO2_1 | G9: =G8 -> 0.00081884742 | H9: input-driver
A10: all states | B10: trn_freight | C10: Freight Rail | D10: Liquids | E10: 2020 | F10: NOx | G10: =TimeSeries!C5 -> 0.92651454 | H10: input-driver
A11: all states | B11: trn_freight | C11: Freight Rail | D11: Liquids | E11: 2025 | F11: NOx | G11: =TimeSeries!D5 -> 0.70138016 | H11: input-driver
A12: all states | B12: trn_freight | C12: Freight Rail | D12: Liquids | E12: 2030 | F12: NOx | G12: =TimeSeries!E5 -> 0.51954086 | H12: input-driver
A13: all states | B13: trn_freight | C13: Freight Rail | D13: Liquids | E13: 2035 | F13: NOx | G13: =TimeSeries!F5 -> 0.37233762 | H13: input-driver
A14: all states | B14: trn_freight | C14: Freight Rail | D14: Liquids | E14: 2040 | F14: NOx | G14: =TimeSeries!G5 -> 0.27708846 | H14: input-driver
A15: all states | B15: trn_freight | C15: Freight Rail | D15: Liquids | E15: 2045 | F15: NOx | G15: =TimeSeries!G5 -> 0.27708846 | H15: input-driver
A16: all states | B16: trn_freight | C16: Freight Rail | D16: Liquids | E16: 2050 | F16: NOx | G16: =TimeSeries!G5 -> 0.27708846 | H16: input-driver
A17: all states | B17: trn_freight | C17: Freight Rail | D17: Liquids | E17: 2020 | F17: PM10 | G17: =TimeSeries!C9 -> 0.027134688 | H17: input-driver
A18: all states | B18: trn_freight | C18: Freight Rail | D18: Liquids | E18: 2025 | F18: PM10 | G18: =TimeSeries!D9 -> 0.019536976 | H18: input-driver
A19: all states | B19: trn_freight | C19: Freight Rail | D19: Liquids | E19: 2030 | F19: PM10 | G19: =TimeSeries!E9 -> 0.01302465 | H19: input-driver
A20: all states | B20: trn_freight | C20: Freight Rail | D20: Liquids | E20: 2035 | F20: PM10 | G20: =TimeSeries!F9 -> 0.0086831003 | H20: input-driver
A21: all states | B21: trn_freight | C21: Freight Rail | D21: Liquids | E21: 2040 | F21: PM10 | G21: =TimeSeries!G9 -> 0.0054269377 | H21: input-driver
A22: all states | B22: trn_freight | C22: Freight Rail | D22: Liquids | E22: 2045 | F22: PM10 | G22: =TimeSeries!G9 -> 0.0054269377 | H22: input-driver
A23: all states | B23: trn_freight | C23: Freight Rail | D23: Liquids | E23: 2050 | F23: PM10 | G23: =TimeSeries!G9 -> 0.0054269377 | H23: input-driver
A24: all states | B24: trn_freight | C24: Freight Rail | D24: Liquids | E24: 2020 | F24: PM2.5 | G24: =TimeSeries!C17 -> 0.025540282 | H24: input-driver
A25: all states | B25: trn_freight | C25: Freight Rail | D25: Liquids | E25: 2025 | F25: PM2.5 | G25: =TimeSeries!D17 -> 0.018389003 | H25: input-driver
A26: all states | B26: trn_freight | C26: Freight Rail | D26: Liquids | E26: 2030 | F26: PM2.5 | G26: =TimeSeries!E17 -> 0.012259335 | H26: input-driver
A27: all states | B27: trn_freight | C27: Freight Rail | D27: Liquids | E27: 2035 | F27: PM2.5 | G27: =TimeSeries!F17 -> 0.0081728903 | H27: input-driver
A28: all states | B28: trn_freight | C28: Freight Rail | D28: Liquids | E28: 2040 | F28: PM2.5 | G28: =TimeSeries!G17 -> 0.0051080564 | H28: input-driver
A29: all states | B29: trn_freight | C29: Freight Rail | D29: Liquids | E29: 2045 | F29: PM2.5 | G29: =TimeSeries!G17 -> 0.0051080564 | H29: input-driver
A30: all states | B30: trn_freight | C30: Freight Rail | D30: Liquids | E30: 2050 | F30: PM2.5 | G30: =TimeSeries!G17 -> 0.0051080564 | H30: input-driver
A31: all states | B31: trn_freight | C31: Freight Rail | D31: Liquids | E31: 2020 | F31: NMVOC | G31: =TimeSeries!C13 -> 0.055633251 | H31: input-driver
A32: all states | B32: trn_freight | C32: Freight Rail | D32: Liquids | E32: 2025 | F32: NMVOC | G32: =TimeSeries!D13 -> 0.041062638 | H32: input-driver
A33: all states | B33: trn_freight | C33: Freight Rail | D33: Liquids | E33: 2030 | F33: NMVOC | G33: =TimeSeries!E13 -> 0.030465828 | H33: input-driver
A34: all states | B34: trn_freight | C34: Freight Rail | D34: Liquids | E34: 2035 | F34: NMVOC | G34: =TimeSeries!F13 -> 0.022518221 | H34: input-driver
A35: all states | B35: trn_freight | C35: Freight Rail | D35: Liquids | E35: 2040 | F35: NMVOC | G35: =TimeSeries!G13 -> 0.017219816 | H35: input-driver
A36: all states | B36: trn_freight | C36: Freight Rail | D36: Liquids | E36: 2045 | F36: NMVOC | G36: =TimeSeries!G13 -> 0.017219816 | H36: input-driver
A37: all states | B37: trn_freight | C37: Freight Rail | D37: Liquids | E37: 2050 | F37: NMVOC | G37: =TimeSeries!G13 -> 0.017219816 | H37: input-driver
A38: all states | B38: trn_pass | C38: Passenger Rail | D38: Liquids | E38: 2020 | F38: NOx | G38: =TimeSeries!C6 -> 0.84217428 | H38: input-driver
A39: all states | B39: trn_pass | C39: Passenger Rail | D39: Liquids | E39: 2025 | F39: NOx | G39: =TimeSeries!D6 -> 0.61578334 | H39: input-driver
A40: all states | B40: trn_pass | C40: Passenger Rail | D40: Liquids | E40: 2030 | F40: NOx | G40: =TimeSeries!E6 -> 0.44372623 | H40: input-driver
A41: all states | B41: trn_pass | C41: Passenger Rail | D41: Liquids | E41: 2035 | F41: NOx | G41: =TimeSeries!F6 -> 0.29883603 | H41: input-driver
...

Sheet TimeSeries
A2: Uses 2015 values from GCAM as starting points. Follows trends from RIA
A4: NOx | B4: 2015 | C4: 2020 | D4: 2025 | E4: 2030 | F4: 2035 | G4: 2040 | H4: 2045 | I4: 2050
A5: Freight | B5: =InitData!J4 -> 1.186285 | C5: =$B5*'Change over time'!C22 -> 0.92651454 | D5: =$B5*'Change over time'!D22 -> 0.70138016 | E5: =$B5*'Change over time'!E22 -> 0.51954086 | F5: =$B5*'Change over time'!F22 -> 0.37233762 | G5: =$B5*'Change over time'!G22 -> 0.27708846 | H5: =$B5*'Change over time'!H22 -> 0.27708846 | I5: =$B5*'Change over time'!I22 -> 0.27708846
A6: Pass | B6: =InitData!J5 -> 1.1862885 | C6: =$B6*'Change over time'!C23 -> 0.84217428 | D6: =$B6*'Change over time'!D23 -> 0.61578334 | E6: =$B6*'Change over time'!E23 -> 0.44372623 | F6: =$B6*'Change over time'!F23 -> 0.29883603 | G6: =$B6*'Change over time'!G23 -> 0.20827966 | H6: =$B6*'Change over time'!H23 -> 0.20827966 | I6: =$B6*'Change over time'!I23 -> 0.20827966
A8: PM10 | B8: 2015 | C8: 2020 | D8: 2025 | E8: 2030 | F8: 2035 | G8: 2040 | H8: 2045 | I8: 2050
A9: Freight | B9: =InitData!K4 -> 0.037988564 | C9: =$B9*'Change over time'!C26 -> 0.027134688 | D9: =$B9*'Change over time'!D26 -> 0.019536976 | E9: =$B9*'Change over time'!E26 -> 0.01302465 | F9: =$B9*'Change over time'!F26 -> 0.0086831003 | G9: =$B9*'Change over time'!G26 -> 0.0054269377 | H9: =$B9*'Change over time'!H26 -> 0.0054269377 | I9: =$B9*'Change over time'!I26 -> 0.0054269377
A10: Pass | B10: =InitData!K5 -> 0.042750766 | C10: =$B10*'Change over time'!C27 -> 0.026404885 | D10: =$B10*'Change over time'!D27 -> 0.017603257 | E10: =$B10*'Change over time'!E27 -> 0.010059004 | F10: =$B10*'Change over time'!F27 -> 0.0062868774 | G10: =$B10*'Change over time'!G27 -> 0.0037721264 | H10: =$B10*'Change over time'!H27 -> 0.0037721264 | I10: =$B10*'Change over time'!I27 -> 0.0037721264
A12: VOC | B12: 2015 | C12: 2020 | D12: 2025 | E12: 2030 | F12: 2035 | G12: 2040 | H12: 2045 | I12: 2050
A13: Freight | B13: =InitData!M4 -> 0.083449877 | C13: =$B13*'Change over time'!C30 -> 0.055633251 | D13: =$B13*'Change over time'!D30 -> 0.041062638 | E13: =$B13*'Change over time'!E30 -> 0.030465828 | F13: =$B13*'Change over time'!F30 -> 0.022518221 | G13: =$B13*'Change over time'!G30 -> 0.017219816 | H13: =$B13*'Change over time'!H30 -> 0.017219816 | I13: =$B13*'Change over time'!I30 -> 0.017219816
A14: Pass | B14: =InitData!M5 -> 0.085754264 | C14: =$B14*'Change over time'!C31 -> 0.045834175 | D14: =$B14*'Change over time'!D31 -> 0.029570436 | E14: =$B14*'Change over time'!E31 -> 0.017742261 | F14: =$B14*'Change over time'!F31 -> 0.010349653 | G14: =$B14*'Change over time'!G31 -> 0.007392609 | H14: =$B14*'Change over time'!H31 -> 0.007392609 | I14: =$B14*'Change over time'!I31 -> 0.007392609
A16: PM2.5 | B16: 2015 | C16: 2020 | D16: 2025 | E16: 2030 | F16: 2035 | G16: 2040 | H16: 2045 | I16: 2050
A17: Freight | B17: =InitData!L4 -> 0.035756395 | C17: =$B17*'Change over time'!C34 -> 0.025540282 | D17: =$B17*'Change over time'!D34 -> 0.018389003 | E17: =$B17*'Change over time'!E34 -> 0.012259335 | F17: =$B17*'Change over time'!F34 -> 0.0081728903 | G17: =$B17*'Change over time'!G34 -> 0.0051080564 | H17: =$B17*'Change over time'!H34 -> 0.0051080564 | I17: =$B17*'Change over time'!I34 -> 0.0051080564
A18: Pass | B18: =InitData!L5 -> 0.035756598 | C18: =$B18*'Change over time'!C35 -> 0.022084957 | D18: =$B18*'Change over time'!D35 -> 0.014723305 | E18: =$B18*'Change over time'!E35 -> 0.0084133171 | F18: =$B18*'Change over time'!F35 -> 0.0052583232 | G18: =$B18*'Change over time'!G35 -> 0.0031549939 | H18: =$B18*'Change over time'!H35 -> 0.0031549939 | I18: =$B18*'Change over time'!I35 -> 0.0031549939

Sheet sulfur
B1: SO2 emissions from emissions modeling platform
C2: 2016fj | D2: 2023fj | E2: 2026fj | F2: 2032fj
B3: rail | C3: 456.97586 | D3: 460.37173 | E3: 468.00022 | F3: 466.21934 | G3: tons
B5: converted to Tg
C6: 2016fj | D6: 2023fj | E6: 2026fj | F6: 2032fj
B7: rail | C7: =C3*0.9071847/1000000 -> 0.00041456151 | D7: =D3*0.9071847/1000000 -> 0.00041764219 | E7: =E3*0.9071847/1000000 -> 0.00042456264 | F7: =F3*0.9071847/1000000 -> 0.00042294705 | G7: Tg
B9: Fuel use (EJ)
C10: =InitData!G4+InitData!G5 -> 0.50627442
B12: Emission factor
C13: =C7/C10 -> 0.00081884742

Sheet Change over time
A2: Values for 2015 and 2040 are g/gal from file: rail_emissions_fact_sheet_P100500B.pdf
A5: NOx | B5: 2015 | C5: 2020 | D5: 2025 | E5: 2030 | F5: 2035 | G5: 2040 | H5: 2045 | I5: 2050
A6: Freight | B6: 137 | C6: 107 | D6: 81 | E6: 60 | F6: 43 | G6: 32 | H6: 32 | I6: 32
A7: Pass | B7: 131 | C7: 93 | D7: 68 | E7: 49 | F7: 33 | G7: 23 | H7: 23 | I7: 23
A9: PM10 | B9: 2015 | C9: 2020 | D9: 2025 | E9: 2030 | F9: 2035 | G9: 2040 | H9: 2045 | I9: 2050
A10: Freight | B10: 3.5 | C10: 2.5 | D10: 1.8 | E10: 1.2 | F10: 0.8 | G10: 0.5 | H10: 0.5 | I10: 0.5
A11: Pass | B11: 3.4 | C11: 2.1 | D11: 1.4 | E11: 0.8 | F11: 0.5 | G11: 0.3 | H11: 0.3 | I11: 0.3
A13: VOC | B13: 2015 | C13: 2020 | D13: 2025 | E13: 2030 | F13: 2035 | G13: 2040 | H13: 2045 | I13: 2050 | K13: Overall average factors used for freight (since pass 3% of fuel use in RIA)
A14: Freight | B14: 6.3 | C14: 4.2 | D14: 3.1 | E14: 2.3 | F14: 1.7 | G14: 1.3 | H14: 1.3 | I14: 1.3 | K14: Note: made assumption PM2.5 is 90% of PM10
A15: Pass | B15: 5.8 | C15: 3.1 | D15: 2 | E15: 1.2 | F15: 0.7 | G15: 0.5 | H15: 0.5 | I15: 0.5
K16: Modified to assume 2040 value reflects full implementation of Tier 4 limits
A17: PM2.5 | B17: 2015 | C17: 2020 | D17: 2025 | E17: 2030 | F17: 2035 | G17: 2040 | H17: 2045 | I17: 2050 | K17: This is being applied to all vintages from 2020.
A18: Freight | B18: =0.9*B10 -> 3.15 | C18: =0.9*C10 -> 2.25 | D18: =0.9*D10 -> 1.62 | E18: =0.9*E10 -> 1.08 | F18: =0.9*F10 -> 0.72 | G18: =0.9*G10 -> 0.45 | H18: =0.9*H10 -> 0.45 | I18: =0.9*I10 -> 0.45
A19: Pass | B19: =0.9*B11 -> 3.06 | C19: =0.9*C11 -> 1.89 | D19: =0.9*D11 -> 1.26 | E19: =0.9*E11 -> 0.72 | F19: =0.9*F11 -> 0.45 | G19: =0.9*G11 -> 0.27 | H19: =0.9*H11 -> 0.27 | I19: =0.9*I11 -> 0.27
A21: NOx | B21: 2015 | C21: 2020 | D21: 2025 | E21: 2030 | F21: 2035 | G21: 2040 | H21: 2045 | I21: 2050
A22: Freight | B22: =B6/$B6 -> 1 | C22: =C6/$B6 -> 0.7810219 | D22: =D6/$B6 -> 0.59124088 | E22: =E6/$B6 -> 0.4379562 | F22: =F6/$B6 -> 0.31386861 | G22: =G6/$B6 -> 0.23357664 | H22: =H6/$B6 -> 0.23357664 | I22: =I6/$B6 -> 0.23357664
A23: Pass | B23: =B7/$B7 -> 1 | C23: =C7/$B7 -> 0.70992366 | D23: =D7/$B7 -> 0.51908397 | E23: =E7/$B7 -> 0.3740458 | F23: =F7/$B7 -> 0.2519084 | G23: =G7/$B7 -> 0.17557252 | H23: =H7/$B7 -> 0.17557252 | I23: =I7/$B7 -> 0.17557252
A25: PM10 | B25: 2015 | C25: 2020 | D25: 2025 | E25: 2030 | F25: 2035 | G25: 2040 | H25: 2045 | I25: 2050
A26: Freight | B26: =B10/$B10 -> 1 | C26: =C10/$B10 -> 0.71428571 | D26: =D10/$B10 -> 0.51428571 | E26: =E10/$B10 -> 0.34285714 | F26: =F10/$B10 -> 0.22857143 | G26: =G10/$B10 -> 0.14285714 | H26: =H10/$B10 -> 0.14285714 | I26: =I10/$B10 -> 0.14285714
A27: Pass | B27: =B11/$B11 -> 1 | C27: =C11/$B11 -> 0.61764706 | D27: =D11/$B11 -> 0.41176471 | E27: =E11/$B11 -> 0.23529412 | F27: =F11/$B11 -> 0.14705882 | G27: =G11/$B11 -> 0.088235294 | H27: =H11/$B11 -> 0.088235294 | I27: =I11/$B11 -> 0.088235294
A29: VOC | B29: 2015 | C29: 2020 | D29: 2025 | E29: 2030 | F29: 2035 | G29: 2040 | H29: 2045 | I29: 2050
A30: Freight | B30: =B14/$B14 -> 1 | C30: =C14/$B14 -> 0.66666667 | D30: =D14/$B14 -> 0.49206349 | E30: =E14/$B14 -> 0.36507937 | F30: =F14/$B14 -> 0.26984127 | G30: =G14/$B14 -> 0.20634921 | H30: =H14/$B14 -> 0.20634921 | I30: =I14/$B14 -> 0.20634921
A31: Pass | B31: =B15/$B15 -> 1 | C31: =C15/$B15 -> 0.53448276 | D31: =D15/$B15 -> 0.34482759 | E31: =E15/$B15 -> 0.20689655 | F31: =F15/$B15 -> 0.12068966 | G31: =G15/$B15 -> 0.086206897 | H31: =H15/$B15 -> 0.086206897 | I31: =I15/$B15 -> 0.086206897
A33: PM2.5 | B33: 2015 | C33: 2020 | D33: 2025 | E33: 2030 | F33: 2035 | G33: 2040 | H33: 2045 | I33: 2050
A34: Freight | B34: =B18/$B18 -> 1 | C34: =C18/$B18 -> 0.71428571 | D34: =D18/$B18 -> 0.51428571 | E34: =E18/$B18 -> 0.34285714 | F34: =F18/$B18 -> 0.22857143 | G34: =G18/$B18 -> 0.14285714 | H34: =H18/$B18 -> 0.14285714 | I34: =I18/$B18 -> 0.14285714
A35: Pass | B35: =B19/$B19 -> 1 | C35: =C19/$B19 -> 0.61764706 | D35: =D19/$B19 -> 0.41176471 | E35: =E19/$B19 -> 0.23529412 | F35: =F19/$B19 -> 0.14705882 | G35: =G19/$B19 -> 0.088235294 | H35: =H19/$B19 -> 0.088235294 | I35: =I19/$B19 -> 0.088235294

Sheet InitData
J1: 2015 EF | N1: 2020 EF
N2: 0.2 | O2: 0.1 | P2: 0.1 | Q2: 0.175
A3: scenario | B3: region | C3: sector | D3: subsector | E3: technology | F3: input | G3: 2015 | H3: Units | J3: NOx | K3: PM10 | L3: PM25 | M3: VOC | N3: NOx | O3: PM10 | P3: PM25 | Q3: VOC
A4: GCAM5p4-Ref-ap,date=2022-3-5T17:56:37-04:00 | B4: Total | C4: trn_freight | D4: Freight Rail | E4: Liquids | F4: refined liquids enduse | G4: 0.48555889 | H4: EJ | J4: =G8/G4 -> 1.186285 | K4: =G10/G4 -> 0.037988564 | L4: =G9/G4 -> 0.035756395 | M4: =G12/G4 -> 0.083449877 | N4: =N$2*J4 -> 0.23725699 | O4: =O$2*K4 -> 0.0037988564 | P4: =P$2*L4 -> 0.0035756395 | Q4: =Q$2*M4 -> 0.014603728
A5: GCAM5p4-Ref-ap,date=2022-3-5T17:56:37-04:00 | B5: Total | C5: trn_pass | D5: Passenger Rail | E5: Liquids | F5: refined liquids enduse | G5: 0.02071553 | H5: EJ | J5: =G14/G5 -> 1.1862885 | K5: =G16/G10 -> 0.042750766 | L5: =G15/G5 -> 0.035756598 | M5: =G18/G5 -> 0.085754264 | N5: =N$2*J5 -> 0.2372577 | O5: =O$2*K5 -> 0.0042750766 | P5: =P$2*L5 -> 0.0035756598 | Q5: =Q$2*M5 -> 0.015006996
A7: scenario | B7: region | C7: sector | D7: subsector | E7: technology | F7: GHG | G7: 2015 | H7: Units
A8: GCAM5p4-Ref-ap,date=2022-3-5T17:56:37-04:00 | B8: Total | C8: trn_freight | D8: Freight Rail | E8: Liquids | F8: NOx | G8: 0.57601122 | H8: Tg
A9: GCAM5p4-Ref-ap,date=2022-3-5T17:56:37-04:00 | B9: Total | C9: trn_freight | D9: Freight Rail | E9: Liquids | F9: PM2.5 | G9: 0.017361836 | H9: Tg
A10: GCAM5p4-Ref-ap,date=2022-3-5T17:56:37-04:00 | B10: Total | C10: trn_freight | D10: Freight Rail | E10: Liquids | F10: PM10 | G10: 0.018445685 | H10: Tg
A11: GCAM5p4-Ref-ap,date=2022-3-5T17:56:37-04:00 | B11: Total | C11: trn_freight | D11: Freight Rail | E11: Liquids | F11: SO2 | G11: 0.11254733 | H11: Tg
A12: GCAM5p4-Ref-ap,date=2022-3-5T17:56:37-04:00 | B12: Total | C12: trn_freight | D12: Freight Rail | E12: Liquids | F12: NMVOC | G12: 0.04051983 | H12: Tg
A14: GCAM5p4-Ref-ap,date=2022-3-5T17:56:37-04:00 | B14: Total | C14: trn_pass | D14: Passenger Rail | E14: Liquids | F14: NOx | G14: 0.024574595 | H14: Tg
A15: GCAM5p4-Ref-ap,date=2022-3-5T17:56:37-04:00 | B15: Total | C15: trn_pass | D15: Passenger Rail | E15: Liquids | F15: PM2.5 | G15: 0.00074071686 | H15: Tg
A16: GCAM5p4-Ref-ap,date=2022-3-5T17:56:37-04:00 | B16: Total | C16: trn_pass | D16: Passenger Rail | E16: Liquids | F16: PM10 | G16: 0.00078856717 | H16: Tg
A17: GCAM5p4-Ref-ap,date=2022-3-5T17:56:37-04:00 | B17: Total | C17: trn_pass | D17: Passenger Rail | E17: Liquids | F17: SO2 | G17: 0.0048017045 | H17: Tg
A18: GCAM5p4-Ref-ap,date=2022-3-5T17:56:37-04:00 | B18: Total | C18: trn_pass | D18: Passenger Rail | E18: Liquids | F18: NMVOC | G18: 0.001776445 | H18: Tg
